Workbook

Sheet OfertaPlazas
A1: Columna1 | B1: UNIVERSIDAD | C1: UNIVERSIDAD (denominación en MoveOn) | D1: CIUDAD | E1: CÓDIGO ERASMUS | F1: PAÍS | G1: Universidades con DT (duración DT) | H1: Deadline 1 FALL SEMESTER | I1: Deadline 1S NOMINACIÓN (OI) | J1: Deadline 1S APLICACIÓN (alumno) | K1: Deadline 2 SPRING SEMESTER | L1: Deadline 2S NOMINACIÓN (OI) | M1: Deadline 2S APLICACIÓN (alumno) | N1: PROGRAMA | O1: Code SECD: 713-Electrical Engineering (Electricity and Energy) | P1: Code SECD: 714-Electrical Engineering (Electronics and Automation) | Q1: Code SECD: 061-Computer Science (Information and Communication Technologies) | R1: Code SECD: 914-Biomedical Engineering (Medical Diagnostic and Treatment Technology) | S1: Area de Estudios | T1: Posibilidad de beca? | U1: PLAZAS | V1: MES | W1: E-mail contacto | X1: Persona de contacto | Y1: GRADOS | Z1: GITST | AA1: GIB | AB1: GISD | AC1: MASTER | AD1: TITULACIÓN | AE1: S5 | AF1: S6 | AG1: C3 | AH1: S7 | AI1: S8 | AJ1: S7+T | AK1: S8+T | AL1: C4º | AM1: C4º+T | AN1: T | AO1: MS2ºAÑO (UN SEMESTRE) | AP1: MS2ºAÑO+TFM | AQ1: TFM | AR1: DT(MASTER) | AS1: CERT | AT1: OBSERVACIONES IDIOMAS | AU1: OBSERVACIONES | AV1: OBSERVACIONES2 | AW1: ToR verificable | AX1: GICO_CODE | AY1: Acuerdo desde la Universidad de origen | AZ1: Areas de estudios | BA1: Departamento Uni de destino | BB1: Contact | BC1: Acuerdo desde la ETSIT-UPM | BD1: Observaciones3 | BE1: OBSERVACIONES (archivo Teams) | BF1: Universidades que contestaron la encuesta | BG1: UNIVERSIDADES QUE NO ESTÁN EN TEAMS
A2: 1 | B2: Technische Universität Graz | C2: Technische Universität Graz | D2: Graz | E2: A GRAZ02 | F2: AT | H2: 10 de abril (nomination) -17 de abril (application) | I2: 04.10 | J2: 04.17 | K2: 16 de octubre (nomination) - 1 de noviembre (application) | L2: 10.16 | M2: 11.01 | N2: ER | Q2: SÍ | R2: SÍ | S2: Computer Science (Information and CommunicationTechnologies) / Biomedical Engineering (Medical Diagnostic and Treatment Technology) | T2: Sí | U2: 3 | V2: 10 | W2: erasmus.incoming@tugraz.at | X2: Kerry John (she/her) | Y2: SI | Z2: SI | AA2: SI | AB2: SI | AC2: SI | AD2: =_xlfn.TEXTJOIN("/",TRUE,IF(OfertaPlazas[[#This Row],[GITST]]="SI","GITST",""),IF(OfertaPlazas[[#This Row],[GIB]]="SI","GIB",""),IF(OfertaPlazas[[#This Row],[GISD]]="SI","GISD",""),IF(OfertaPlazas[[#This Row],[MASTER]]="SI","MASTER","")) -> GITST/GIB/GISD/MASTER | AE2: SI | AF2: SI | AG2: SI | AH2: SI | AI2: SI | AJ2: SI | AK2: SI | AL2: SI | AM2: SI | AN2: SI | AO2: SI | AP2: SI | AQ2: SI | AR2: NO | AS2: ALEMÁN B2 o INGLÉS B2 | AT2: INGLÉS B2 (TOEFL 75, IELTS 6.0, TOEIC (785 listening and reading - 310 speaking and writing), Cambridge ESOL First Certificate in English (FCE) OR Certificate in Advanced English (CAE) OR Certificate of Proficiency in English (CPE) or Certificate issued by the language centre of a University | AU2: Sólo se puede hacerse el TFG/TFM si un profesor acepta al alumno. El área de estudios para alumnos de GITST y MUIT es computer science. | AV2: se puede desdoblar nº de meses | AW2: ToR verificable | AX2: ToR verificable | AY2: Departamental | AZ2: Computer Science y Biomedical Engineering | BA2: Computer Science | BC2: ETSIT | BE2: =VLOOKUP(B2,'TEAMS_30-09-2021'!$D:$AG,30,FALSE) -> 0 | BF2: =VLOOKUP(B2,'ENCUESTAS JUN-2021'!I:I,1,FALSE) -> #N/A | BG2: =VLOOKUP(B2,'TEAMS_30-09-2021'!D:D,1,FALSE) -> Technische Universität Graz
A3: 2 | B3: FH Joanneum | C3: FH JOANNEUM - University of Applied Sciences | D3: Graz | E3: A GRAZ09 | F3: AT | H3: 1 de junio (nomination) 15 de junio (application) | I3: 06.01 | J3: 06.15 | K3: 1 de noviembre (nomination) - 15 de noviembre (application) | L3: 11.01 | M3: 11.15 | N3: ER | P3: SÍ | S3: Electrical Engineering (Electronics and Automation) | T3: Sí | U3: 2 | V3: 10 | W3: international@fh-joanneum.at; incoming-students@fh-joanneum.at | X3: Regina Käfer-Goiginger | Y3: SI | Z3: SI | AA3: NO | AB3: NO | AC3: SI | AD3: =_xlfn.TEXTJOIN("/",TRUE,IF(OfertaPlazas[[#This Row],[GITST]]="SI","GITST",""),IF(OfertaPlazas[[#This Row],[GIB]]="SI","GIB",""),IF(OfertaPlazas[[#This Row],[GISD]]="SI","GISD",""),IF(OfertaPlazas[[#This Row],[MASTER]]="SI","MASTER","")) -> GITST/MASTER | AE3: SI | AF3: SI | AG3: SI | AH3: SI | AI3: SI | AJ3: SI | AK3: SI | AL3: SI | AM3: SI | AN3: SI | AO3: SI | AP3: SI | AQ3: SI | AR3: NO | AS3: ALEMÁN B2 o INGLÉS B2 | AU3: https://www.fh-joanneum.at/en/international/study-programmes/international-programme-kapfenberg/ https://www.fh-joanneum.at/en/international/study-programmes/ | AV3: se puede desdoblar nº de meses / se quita el área de bio mayo 2026
A4: 3 | B4: MCI | THE ENTREPRENEURIAL SCHOOL | C4: MCI - Management Center Innsbruck | D4: Innsbruck | E4: A INNSBRU08 | F4: AT | H4: 1 de abril (nomination) 1 de mayo (application) | I4: 04.01 | J4: 05.01 | K4: 1 de octubre (nomination) - 1 de noviembre (application) | L4: 10.01 | M4: 11.01 | N4: ER | P4: SÍ | Q4: SÍ | R4: SÍ | S4: Electrical Engineering (Electronics and Automation) / Biomedical Engineering (Medical Diagnosticand Treatment Technology) /Computer Science (Information and CommunicationTechnologies) | T4: Sí | U4: 2 | V4: 10 | W4: Daniel.Dassisi@mci.edu; incoming@mci.edu | X4: Daniel D'Assissi | Y4: SI | Z4: SI | AA4: SI | AB4: SI | AC4: SI | AD4: =_xlfn.TEXTJOIN("/",TRUE,IF(OfertaPlazas[[#This Row],[GITST]]="SI","GITST",""),IF(OfertaPlazas[[#This Row],[GIB]]="SI","GIB",""),IF(OfertaPlazas[[#This Row],[GISD]]="SI","GISD",""),IF(OfertaPlazas[[#This Row],[MASTER]]="SI","MASTER","")) -> GITST/GIB/GISD/MASTER | AE4: SI | AF4: NO | AG4: NO | AH4: SI | AI4: NO | AJ4: SI | AK4: NO | AL4: NO | AM4: NO | AN4: SI | AO4: SI | AP4: SI | AQ4: SI | AR4: NO | AS4: INGLÉS B2 o INGLÉS C1 o ALEMÁN B1 | AT4: GRADO:INGLÉS B2 (TOEFL iBT ≥ 75 o TOEFL pBT ≥ 540 o IELTS Academic ≥ 5.5 o PTE Academic ≥ 50 o Cambridge English BEC Vantage ≥ 160 o CAE ≥ 160 o Oxford Test of English ≥ 111 en todas las destrezas o LanguageCert Academic ≥ 60) MÁSTER:INGLÉS C1 (TOEFL iBT ≥ 85 o TOEFL pBT ≥ 560 o IELTS Academic ≥ 6.5 o PTE Academic ≥ 65 o Cambridge English BEC Higher ≥ 180 o CAE ≥ 180 o Cambridge English Proficiency (CPE) ≥ 200 o Oxford Test of English ≥ 120 en todas las destrezas o LanguageCert Academic ≥ 75) o ALEMÁN B1 (www.mci.edu/exchange-incoming) | AU4: On undergraduate level, the courses are only offered in the fall semester // No permiten coger asignaturas de varios materes por tema de solapamiento de horarios | AV4: Acuerdo firmado en septiembre 2022 - se puede desdoblar nº de meses
A5: 4 | B5: Technische Universität Wien | C5: Technische Universität Wien | D5: Viena | E5: A WIEN02 | F5: AT | H5: 31 de mayo (nomination) -30 junio (application) | I5: 05.31 | J5: 06.30 | K5: 15 de diciembre (nomination)- 31 de diciembre (application) | L5: 12.15 | M5: 12.31 | N5: ER | P5: SÍ | R5: SÍ | S5: Electrical Engineering (Electronics and Automation) / Biomedical Engineering (Medical Diagnosticand Treatment Technology) | T5: Sí | U5: 4 | V5: 10 | W5: exchangein@tuwien.ac.at | X5: international office | Y5: SI | Z5: SI | AA5: NO | AB5: NO | AC5: SI | AD5: =_xlfn.TEXTJOIN("/",TRUE,IF(OfertaPlazas[[#This Row],[GITST]]="SI","GITST",""),IF(OfertaPlazas[[#This Row],[GIB]]="SI","GIB",""),IF(OfertaPlazas[[#This Row],[GISD]]="SI","GISD",""),IF(OfertaPlazas[[#This Row],[MASTER]]="SI","MASTER","")) -> GITST/MASTER | AE5: SI | AF5: SI | AG5: SI | AH5: SI | AI5: SI | AJ5: SI | AK5: SI | AL5: SI | AM5: SI | AN5: SI | AO5: SI | AP5: SI | AQ5: SI | AR5: NO | AS5: ALEMÁN B1 o ALEMÁN A2 o INGLÉS B1 | AT5: Junto con curso intentivo de alemán.Se acepta el certificado del departamento de lingüística | AU5: En la solicitud online hay que registrarse como Master students. Asignaturas en INGLÉS sólo a nivel MASTER. Para poder realizar el TFM ponen como condición necesaria el tener un tutor y un tema para el TFM prevío a la llegada, dan una oferta de TFMs y hay que coger uno o renunciar a hacer el TFM. Se puede coger algunas asignaturas de la Faculty of informatics | AV5: se puede desdoblar nº de meses | AY5: Institucional | AZ5: Electrical Engineering | BC5: UPM (varias Escuelas) | BD5: se añade el área de bio | BE5: =VLOOKUP(B5,'TEAMS_30-09-2021'!$D:$AG,30,FALSE) -> se añade el área de bio acordado con TU Wien | BF5: =VLOOKUP(B5,'ENCUESTAS JUN-2021'!I:I,1,FALSE) -> #N/A | BG5: =VLOOKUP(B5,'TEAMS_30-09-2021'!D:D,1,FALSE) -> Technische Universität Wien
A6: 5 | B6: Université Libre de Bruxelles ULB - Ecole Polytechnique de Bruxelles | C6: Université Libre de Bruxelles | D6: Bruselas | E6: B BRUXEL04 | F6: BE | H6: 15 de mayo (nomination) 1 de junio (application) | I6: 05.15 | J6: 06.01 | K6: 15 de octubre (nomination) - 30 de octubre (application) | L6: 10.15 | M6: 10.30 | N6: ER | P6: SÍ | R6: SÍ | S6: Electrical Engineering (Electronics and Automation) / Biomedical Engineering (Medical Diagnosticand Treatment Technology) | T6: Sí | U6: 2 | V6: 12 | W6: mobilite@ulb.be; international.polytech@ulb.be; alice.hoslet@ulb.be | X6: Hoslet Alice; Rose-Marie Brynaert (EPB) | Y6: SI | Z6: SI | AA6: SI | AB6: NO | AC6: SI | AD6: =_xlfn.TEXTJOIN("/",TRUE,IF(OfertaPlazas[[#This Row],[GITST]]="SI","GITST",""),IF(OfertaPlazas[[#This Row],[GIB]]="SI","GIB",""),IF(OfertaPlazas[[#This Row],[GISD]]="SI","GISD",""),IF(OfertaPlazas[[#This Row],[MASTER]]="SI","MASTER","")) -> GITST/GIB/MASTER | AE6: SI | AF6: SI | AG6: SI | AH6: SI | AI6: SI | AJ6: SI | AK6: SI | AL6: SI | AM6: SI | AN6: NO | AO6: SI | AP6: SI | AQ6: SI | AR6: NO | AS6: FRANCÉS B1 o INGLÉS B1 | AU6: Sólo se puede hacer TFG con asignaturas que incluyan un proyecto. Se requiere cursar 15ECTS de asignaturas (a parte del TFG). ENG para el Master en ingeniería eléctrica. Se debe encontrar un "Promoter" para realizar el research project (TFM) antes del 1 de junio. | AV6: se puede desdoblar nº de meses | AY6: Institucional | AZ6: Electrical Engineering | BC6: UPM (varias Escuelas) | BD6: OJO: hay que añadir biomedical engineering en la renovación. Ya acordada | BE6: =VLOOKUP(B6,'TEAMS_30-09-2021'!$D:$AG,30,FALSE) -> #N/A | BF6: =VLOOKUP(B6,'ENCUESTAS JUN-2021'!I:I,1,FALSE) -> #N/A | BG6: =VLOOKUP(B6,'TEAMS_30-09-2021'!D:D,1,FALSE) -> #N/A | BL6: =VLOOKUP(E6,#REF!,1,FALSE) -> #REF!
A7: 6 | B7: Universiteit Gent | C7: Universiteit Gent | D7: Gent | E7: B GENT01 | F7: BE | H7: 15 de abril (nomination) 15 de mayo (application) | I7: 04.15 | J7: 05.15 | K7: 15 octubre(nomination) - 15 de noviembre(application) | L7: 10.15 | M7: 11.15 | N7: ER | P7: SÍ | R7: SÍ | S7: Electrical Engineering (Electronics and Automation) / Biomedical Engineering (Medical Diagnosticand Treatment Technology) | T7: Sí | U7: 4 | V7: 12 | W7: international.ea@ugent.be; outgoing.students@ugent.be; internationalsupport@ugent.be | X7: Ann Vanoutryve | Y7: SI | Z7: SI | AA7: SI | AB7: NO | AC7: SI | AD7: =_xlfn.TEXTJOIN("/",TRUE,IF(OfertaPlazas[[#This Row],[GITST]]="SI","GITST",""),IF(OfertaPlazas[[#This Row],[GIB]]="SI","GIB",""),IF(OfertaPlazas[[#This Row],[GISD]]="SI","GISD",""),IF(OfertaPlazas[[#This Row],[MASTER]]="SI","MASTER","")) -> GITST/GIB/MASTER | AE7: SI | AF7: SI | AG7: SI | AH7: SI | AI7: SI | AJ7: SI | AK7: SI | AL7: SI | AM7: SI | AN7: SI | AO7: SI | AP7: SI | AQ7: SI | AR7: NO | AS7: INGLÉS B2 o HOLANDÉS B2 | AT7: INGLÉS B2: TOEFL min 87 o IELTS 6,0 (min 6,0 in writing) o TOEIC min 785 o FCE, CAE, CPE o University language Center certifying a level B2 o HOLANDES B2 (proof that the student finished successfully a Dutch study programme of at least 1 year) | AU7: 2 plazas para Biomedical Engineering y 2 plazas para Electrical Engineering (se puede nominar solamente en un área) | AV7: La solicitud de alojamiento abre a ppio de abril así que es mejor hacer la e-nomination pronto aunque el deadline es 15/05 Se puede pasar alumnos del área de teleco al área de bio sin pasarse del número total de alumnos | AW7: No envían ToR en papel y su ToR no es verificable. Aceptamos el ToR si lo envía Ugent | AX7: GENT-2 | AY7: Departamental | AZ7: Electrical Engineering y Biomedical Engineering | BA7: Electrical Engineering y Biomedical Engineering | BC7: ETSIT | BE7: =VLOOKUP(B7,'TEAMS_30-09-2021'!$D:$AG,30,FALSE) -> 0 | BF7: =VLOOKUP(B7,'ENCUESTAS JUN-2021'!I:I,1,FALSE) -> Universiteit Gent | BG7: =VLOOKUP(B7,'TEAMS_30-09-2021'!D:D,1,FALSE) -> Universiteit Gent | BL7: =VLOOKUP(E7,#REF!,1,FALSE) -> #REF!
A8: 7 | B8: Katholike Universiteit Leuven | C8: KU Leuven | D8: Leuven | E8: B LEUVEN01 | F8: BE | H8: 30 de abril | I8: 04.15 | J8: 04.30 | K8: 1 de octubre | L8: 10.01 | N8: ER | P8: SÍ | R8: SÍ | S8: Electrical Engineering (Electronics and Automation) / Biomedical Engineering (Medical Diagnosticand Treatment Technology) | T8: Sí | U8: 2 | V8: 12 | W8: viktoriia.pukhyr@kuleuven.be | X8: Viktoriia Pukhyr | Y8: SI | Z8: SI | AA8: SI | AB8: NO | AC8: SI | AD8: =_xlfn.TEXTJOIN("/",TRUE,IF(OfertaPlazas[[#This Row],[GITST]]="SI","GITST",""),IF(OfertaPlazas[[#This Row],[GIB]]="SI","GIB",""),IF(OfertaPlazas[[#This Row],[GISD]]="SI","GISD",""),IF(OfertaPlazas[[#This Row],[MASTER]]="SI","MASTER","")) -> GITST/GIB/MASTER | AE8: NO | AF8: NO | AG8: NO | AH8: SI | AI8: SI | AJ8: SI | AK8: SI | AL8: SI | AM8: SI | AN8: SI | AO8: SI | AP8: SI | AQ8: SI | AR8: NO | AS8: INGLÉS B2 | AU8: courses available to exchange students can be found here: https://onderwijsaanbod.kuleuven.be/opleidingen/e/SC_51977178.htm#&bl=all OJO: solo se puede coger 2 asignaturas máximo en la facultad de business | AV8: Se puede dividir el número de meses / pasamos de 3*12 a 2*10 en 2022 / Movilidad a partir de 4º curso / se pide aumentar de 2 a 3 alumnos Indeed, we form agreements mentioning specific study fields (as you mentioned for example Electrical Engineering and Biomedical Engineering), but incoming exchange students are allowed to take courses from any of our Master's programmes at our Faculty | AW8: ToR verificable | AX8: ToR verificable | AY8: Departamental | AZ8: Electrical Engineering y Biomedical Engineering | BA8: Faculty of Engineering Science | BC8: ETSIT | BE8: =VLOOKUP(B8,'TEAMS_30-09-2021'!$D:$AG,30,FALSE) -> 0 | BF8: =VLOOKUP(B8,'ENCUESTAS JUN-2021'!I:I,1,FALSE) -> Katholike Universiteit Leuven | BG8: =VLOOKUP(B8,'TEAMS_30-09-2021'!D:D,1,FALSE) -> Katholike Universiteit Leuven | BL8: =VLOOKUP(E8,#REF!,1,FALSE) -> #REF!
A9: 8 | B9: Université de Liège | C9: Université de Liège | D9: Lieja | E9: B LIEGE01 | F9: BE | H9: 15 de mayo (nomination) - 31 de mayo (application) | I9: 05.15 | J9: 05.31 | K9: 1 de noviembre (online) - 15 de noviembre (impreso) | L9: 11.01 | M9: 11.15 | N9: ER | P9: SÍ | R9: SÍ | S9: Electrical Engineering (Electronics and Automation) / Biomedical Engineering (Medical Diagnosticand Treatment Technology) | T9: Sí | U9: 2 | V9: 12 | W9: mobil.in@uliege.be; marta.kucharska@uliege.be | X9: Marta KUCHARSKA | Y9: SI | Z9: SI | AA9: SI | AB9: NO | AC9: SI | AD9: =_xlfn.TEXTJOIN("/",TRUE,IF(OfertaPlazas[[#This Row],[GITST]]="SI","GITST",""),IF(OfertaPlazas[[#This Row],[GIB]]="SI","GIB",""),IF(OfertaPlazas[[#This Row],[GISD]]="SI","GISD",""),IF(OfertaPlazas[[#This Row],[MASTER]]="SI","MASTER","")) -> GITST/GIB/MASTER | AE9: SI | AF9: SI | AG9: SI | AH9: SI | AI9: SI | AJ9: SI | AK9: SI | AL9: SI | AM9: SI | AN9: SI | AO9: SI | AP9: SI | AQ9: SI | AR9: NO | AS9: FRANCÉS B1 o INGLÉS B2 | AY9: Institucional | AZ9: Electrical Engineering y Biomedical Engineering | BC9: ETSIT | BE9: =VLOOKUP(B9,'TEAMS_30-09-2021'!$D:$AG,30,FALSE) -> 0 | BF9: =VLOOKUP(B9,'ENCUESTAS JUN-2021'!I:I,1,FALSE) -> Université de Liège | BG9: =VLOOKUP(B9,'TEAMS_30-09-2021'!D:D,1,FALSE) -> Université de Liège | BL9: =VLOOKUP(E9,#REF!,1,FALSE) -> #REF!
A10: 9 | B10: Université Catholique de Louvain - EPL | C10: Université Catholique de Louvain | D10: Louvain-la-Neuve | E10: B LOUVAIN01 | F10: BE | H10: 1 de abril (nomination) - 15 de abril (application) | I10: 04.01 | J10: 04.15 | K10: 30 septiembre (nomination) - 31 octubre (application) | L10: 09.30 | M10: 10.31 | N10: ER | P10: SÍ | S10: Electrical Engineering (Electronics and Automation) | T10: Sí | U10: 2 | V10: 12 | W10: emmanuelle.brun@uclouvain.be | X10: Emmanuelle Brun | Y10: SI | Z10: SI | AA10: NO | AB10: NO | AC10: SI | AD10: =_xlfn.TEXTJOIN("/",TRUE,IF(OfertaPlazas[[#This Row],[GITST]]="SI","GITST",""),IF(OfertaPlazas[[#This Row],[GIB]]="SI","GIB",""),IF(OfertaPlazas[[#This Row],[GISD]]="SI","GISD",""),IF(OfertaPlazas[[#This Row],[MASTER]]="SI","MASTER","")) -> GITST/MASTER | AE10: SI | AF10: SI | AG10: SI | AH10: SI | AI10: SI | AJ10: NO | AK10: NO | AL10: SI | AM10: NO | AN10: NO | AO10: SI | AP10: SI | AQ10: SI | AR10: NO | AS10: FRANCÉS B2 o INGLÉS B2 | AT10: FRANCÉS B2 (DELF - DALF) o INGLÉS B2 (TOEFL - IEALTS - CAP - CPE o statement of English language teacher) | AU10: El acuerdo es con EPL (École Polytechnique de Louvain). Bachelor en francés. Máster en inglés. | AY10: Institucional | AZ10: Electronics Engineering | BC10: UPM (varias Escuelas) | BE10: =VLOOKUP(B10,'TEAMS_30-09-2021'!$D:$AG,30,FALSE) -> 0 | BF10: =VLOOKUP(B10,'ENCUESTAS JUN-2021'!I:I,1,FALSE) -> #N/A | BG10: =VLOOKUP(B10,'TEAMS_30-09-2021'!D:D,1,FALSE) -> Université Catholique de Louvain - EPL
A11: 10 | B11: Angel Kanchev University of Ruse | C11: Rusenski Universitet Angel Kunchev | D11: Ruse | E11: BG ROUSSE01 | F11: BG | H11: 30 de junio (application) | I11: 06.30 | J11: 06.30 | K11: 30 de noviembre (application) | L11: 11.30 | M11: 11.30 | N11: ER | P11: SÍ | S11: Electrical Engineering (Electronics and Automation) | T11: Sí | U11: 1 | V11: 12 | W11: tiliev@uni-ruse.bg | X11: Teodor Iliev | Y11: SI | Z11: SI | AA11: NO | AB11: NO | AC11: SI | AD11: =_xlfn.TEXTJOIN("/",TRUE,IF(OfertaPlazas[[#This Row],[GITST]]="SI","GITST",""),IF(OfertaPlazas[[#This Row],[GIB]]="SI","GIB",""),IF(OfertaPlazas[[#This Row],[GISD]]="SI","GISD",""),IF(OfertaPlazas[[#This Row],[MASTER]]="SI","MASTER","")) -> GITST/MASTER | AE11: SI | AF11: SI | AG11: SI | AH11: SI | AI11: SI | AJ11: SI | AK11: SI | AL11: NO | AM11: NO | AN11: SI | AO11: SI | AP11: NO | AQ11: SI | AR11: NO | AS11: INGLÉS B1 | AU11: Posibilidad de cursar asignaturas del Bachelor degree: Information and Communication Technology en inglés | AV11: se puede desdoblar nº de meses | AY11: Departamental | AZ11: Electrical Engineering | BA11: Telecommuncations Department | BC11: ETSIT | BE11: =VLOOKUP(B11,'TEAMS_30-09-2021'!$D:$AG,30,FALSE) -> 0 | BF11: =VLOOKUP(B11,'ENCUESTAS JUN-2021'!I:I,1,FALSE) -> #N/A | BG11: =VLOOKUP(B11,'TEAMS_30-09-2021'!D:D,1,FALSE) -> Angel Kanchev University of Ruse | BL11: =VLOOKUP(E11,#REF!,1,FALSE) -> #REF!
A12: 11 | B12: Technical University of Sofia | C12: Tehnicheski Universitet Sofia | D12: Sofia | E12: BG SOFIA16 | F12: BG | H12: 15 de junio | I12: 06.15 | J12: 06.15 | K12: 15 de noviembre | L12: 11.15 | N12: ER | P12: SÍ | S12: Electrical Engineering (Electronics and Automation) | T12: Sí | U12: 2 | V12: 12 | W12: vkp@tu-sofia.bg | X12: Vladimir Poulkov | Y12: SI | Z12: SI | AA12: NO | AB12: NO | AC12: SI | AD12: =_xlfn.TEXTJOIN("/",TRUE,IF(OfertaPlazas[[#This Row],[GITST]]="SI","GITST",""),IF(OfertaPlazas[[#This Row],[GIB]]="SI","GIB",""),IF(OfertaPlazas[[#This Row],[GISD]]="SI","GISD",""),IF(OfertaPlazas[[#This Row],[MASTER]]="SI","MASTER","")) -> GITST/MASTER | AE12: SI | AF12: SI | AG12: SI | AH12: SI | AI12: SI | AJ12: SI | AK12: SI | AL12: SI | AM12: SI | AN12: SI | AO12: SI | AP12: SI | AQ12: SI | AR12: NO | AS12: INGLÉS B1 | AV12: se puede desdoblar nº de meses | AY12: Departamental | AZ12: Electrical Engineering | BA12: Faculty of Telecommunications | BC12: ETSIT | BE12: =VLOOKUP(B12,'TEAMS_30-09-2021'!$D:$AG,30,FALSE) -> 0 | BF12: =VLOOKUP(B12,'ENCUESTAS JUN-2021'!I:I,1,FALSE) -> #N/A | BG12: =VLOOKUP(B12,'TEAMS_30-09-2021'!D:D,1,FALSE) -> Technical University of Sofia | BL12: =VLOOKUP(E12,#REF!,1,FALSE) -> #REF!
A13: 12 | B13: HES-SO Haute École Spécialisée de Suisse Occidentale - hepia | C13: HES-SO Haute École Spécialisée de Suisse Occidentale | D13: Ginebra | E13: CH DELEMONT03 | F13: CH | H13: 31 de marzo | I13: 03.31 | J13: 03.31 | L13: 03.31 | N13: AB | P13: SÍ | Q13: SÍ | S13: Electrical Engineering (Electronics and Automation) / Computer Science (Information and CommunicationTechnologies) | T13: Sí (beca gobierno Suizo) | U13: 6 | V13: 6 | W13: ri.hepia@hesge.ch; | X13: international office | Y13: SI | Z13: SI | AA13: NO | AB13: SI | AC13: SI | AD13: =_xlfn.TEXTJOIN("/",TRUE,IF(OfertaPlazas[[#This Row],[GITST]]="SI","GITST",""),IF(OfertaPlazas[[#This Row],[GIB]]="SI","GIB",""),IF(OfertaPlazas[[#This Row],[GISD]]="SI","GISD",""),IF(OfertaPlazas[[#This Row],[MASTER]]="SI","MASTER","")) -> GITST/GISD/MASTER | AE13: SI | AF13: SI | AG13: SI | AH13: SI | AI13: SI | AJ13: NO | AK13: NO | AL13: SI | AM13: NO | AN13: NO | AO13: SI | AP13: NO | AQ13: NO | AR13: NO | AS13: FRANCÉS B1 | AT13: (asignaturas de grado SOLO en francés; en master algunas asignaturas en inglés) | AU13: HES-SO Campus en Lausanne y HEPIA campus en Ginebra / 3 alumnos en el área 714 Electronics Engineering Telecommunications y 3 alumnos en el área 611 Informatics, Computer Science. No se puede cursar TFT, solo asignaturas. 30 ECTS por semestre | AY13: Departamental | AZ13: Computer Science | BA13: Engineering of lnformation Technology | BB13: sac-exchange-in@epfl.ch | BC13: ETSIT | BF13: =VLOOKUP(B13,'ENCUESTAS JUN-2021'!I:I,1,FALSE) -> #N/A | BG13: [Universidad suiza, no Erasmus] | BL13: =VLOOKUP(E13,#REF!,1,FALSE) -> #REF!
A14: 13 | B14: École Polytechnique Fédérale de Lausanne - EPFL | C14: École Polytechnique Fédérale (EPF) Lausanne | D14: Lausana | E14: CH LAUSANN06 | F14: CH | H14: 15 de abril | I14: 04.15 | J14: 04.15 | K14: 15 de octubre | L14: 10.15 | N14: AB | O14: Sí | Q14: SÍ | R14: SÍ | S14: Computer Science (Information and CommunicationTechnologies) / Electrical Engineering (Electronics and Automation) / Biomedical Engineering (Medical Diagnosticand Treatment Technology) | T14: Sí (beca gobierno Suizo) | U14: 3 | V14: 10 | W14: sac-exchange-out@epfl.ch, sac-exchange-in@epfl.ch | X14: international office | Y14: SI | Z14: SI | AA14: SI | AB14: SI | AC14: SI | AD14: =_xlfn.TEXTJOIN("/",TRUE,IF(OfertaPlazas[[#This Row],[GITST]]="SI","GITST",""),IF(OfertaPlazas[[#This Row],[GIB]]="SI","GIB",""),IF(OfertaPlazas[[#This Row],[GISD]]="SI","GISD",""),IF(OfertaPlazas[[#This Row],[MASTER]]="SI","MASTER","")) -> GITST/GIB/GISD/MASTER | AE14: SI | AF14: SI | AG14: SI | AH14: SI | AI14: SI | AJ14: SI | AK14: SI | AL14: SI | AM14: SI | AN14: SI | AO14: SI | AP14: SI | AQ14: SI | AR14: NO | AS14: FRANCÉS B2 o INGLÉS B2 | AU14: Nota mínima expediente académico: 7. Bachelor en francés. Master programm en inglés y francés. El alumno debe registrar entre 20/30 créditos ECTS por semestre. Para el TFG, debe solicitar "semester Project" (programa de Máster). No se permite cursar asignaturas en el mismo semestre que se realiza el TFM. The access to courses in our College of Management of Technology (Management of Technology and Entrepreneurship, and Financial Engineering) is not open to exchange students. Asignaturas NO disponibles para alumnos de movilidad: https://www.epfl.ch/education/international/fr/venir-etudier-a-l-epfl/semestres-cours/conditions/ | AV14: se añade el área de bio empezando en 22/23 | AY14: Institucional | AZ14: Electrical Engineering, Computer Science y Biomedical Engineering | BC14: UPM (varias Escuelas) | BD14: Se añade el área biomedical engineering | BF14: =VLOOKUP(B14,'ENCUESTAS JUN-2021'!I:I,1,FALSE) -> #N/A | BG14: [Universidad suiza, no Erasmus] | BL14: =VLOOKUP(E14,#REF!,1,FALSE) -> #REF!
A15: 14 | B15: Zürcher Hochschule für Angewandte Wissenschaften ZHAW | C15: Zürcher Hochschule für Angewandte Wissenschaften | D15: Winterthur | E15: CH WINTERT03 | F15: CH | H15: 15 de marzo (nomination) - 1 de abril (application) | I15: 03.15 | J15: 04.01 | K15: 15 de octubre (nomination) - 1 de noviembre (application) | L15: 10.15 | M15: 11.01 | N15: AB | P15: SÍ | Q15: SÍ | S15: Electrical Engineering (Electronics and Automation) / Computer Science (Information and CommunicationTechnologies) | T15: Sí (beca gobierno Suizo) | U15: 2 | V15: 10 | W15: international.engineering@zhaw.ch; exchange.engineering@zhaw.ch | X15: Sabrina Meizinger | Y15: SI | Z15: SI | AA15: NO | AB15: SI | AC15: SI | AD15: =_xlfn.TEXTJOIN("/",TRUE,IF(OfertaPlazas[[#This Row],[GITST]]="SI","GITST",""),IF(OfertaPlazas[[#This Row],[GIB]]="SI","GIB",""),IF(OfertaPlazas[[#This Row],[GISD]]="SI","GISD",""),IF(OfertaPlazas[[#This Row],[MASTER]]="SI","MASTER","")) -> GITST/GISD/MASTER | AE15: SI | AF15: SI | AG15: SI | AH15: SI | AI15: SI | AJ15: SI | AK15: SI | AL15: SI | AM15: SI | AN15: SI | AO15: SI | AP15: SI | AQ15: SI | AR15: NO | AS15: ALEMÁN B2 o INGLÉS B2 o INGLÉS C1 | AT15: GRADO:ALEMÁN B2 o INGLÉS B2 (TOEFL 550/213/79 o TOEIC 700 o IELTS 6.0 o CAE) / MASTER: INGLÉS C1 forma parte de EELISA | AV15: dic 2022: se renueva el acuerdo con las mismas condiciones | AY15: Departamental | AZ15: Engineering and trade | BA15: Applied mathematics, Physics, Systems and Operations | BC15: ETSIT | BF15: =VLOOKUP(B15,'ENCUESTAS JUN-2021'!I:I,1,FALSE) -> #N/A | BG15: [Universidad suiza, no Erasmus] | BL15: =VLOOKUP(E15,#REF!,1,FALSE) -> #REF!
A16: 15 | B16: Czech Technical University CTU | C16: Ceské Vysoké Uceni Technické v Praze | D16: Prague | E16: CZ PRAHA10 | F16: CZ | H16: 15 de abril(nomination) - 30 abril (application) | I16: 04.15 | J16: 04.30 | K16: 15 noviembre (nomination ) -30 de noviembre (application) | L16: 11.15 | M16: 11.30 | N16: ER | P16: SÍ | S16: Electrical Engineering (Electronics and Automation) | T16: Sí | U16: 2 | V16: 12 | W16: Lucie.Bilova@cvut.cz | X16: Bilova, Lucie | Y16: SI | Z16: SI | AA16: NO | AB16: NO | AC16: SI | AD16: =_xlfn.TEXTJOIN("/",TRUE,IF(OfertaPlazas[[#This Row],[GITST]]="SI","GITST",""),IF(OfertaPlazas[[#This Row],[GIB]]="SI","GIB",""),IF(OfertaPlazas[[#This Row],[GISD]]="SI","GISD",""),IF(OfertaPlazas[[#This Row],[MASTER]]="SI","MASTER","")) -> GITST/MASTER | AE16: SI | AF16: SI | AG16: SI | AH16: SI | AI16: SI | AJ16: SI | AK16: SI | AL16: SI | AM16: SI | AN16: SI | AO16: SI | AP16: SI | AQ16: SI | AR16: NO | AS16: INGLÉS B2 o ALEMÁN B1 | AT16: INGLÉS B2 (se acepta el certificado del departamento de lingüística) | AU16: incoming students are required to collect at least 15 ECTS credits/semester | AV16: se puede desdoblar nº de meses | AW16: 01/03/2023 "We don't post hard copies for sure. The students are many times informed about it. In the case you really need a hard copy and the scanned one sent by the international office isn't enough, I hope the student has some friends here to pick up the hard copy in my office and send it" | AY16: Departamental | AZ16: Electrical Engineering | BA16: Faculty of Electrical Engineering | BC16: ETSIT | BE16: =VLOOKUP(B16,'TEAMS_30-09-2021'!$D:$AG,30,FALSE) -> 0 | BF16: =VLOOKUP(B16,'ENCUESTAS JUN-2021'!I:I,1,FALSE) -> #N/A | BG16: =VLOOKUP(B16,'TEAMS_30-09-2021'!D:D,1,FALSE) -> Czech Technical University CTU | BL16: =VLOOKUP(E16,#REF!,1,FALSE) -> #REF!
A17: 16 | B17: RWTH - Aachen | C17: Rheinisch-Westfälische Technische Hochschule Aachen | D17: Aachen | E17: D AACHEN01 | F17: DE | H17: 31 de marzo (nomination) - 31 de mayo (application) | I17: 03.31 | J17: 05.31 | K17: 31 de octubre (nomination)-31 de diciembre (application) | L17: 10.31 | M17: 12.31 | N17: ER | P17: SÍ | S17: Electrical Engineering (Electronics and Automation) | T17: Sí | U17: 4 | V17: 5 | W17: incomings@rwth-aachen.de | X17: International Office | Y17: SI | Z17: SI | AA17: NO | AB17: NO | AC17: SI | AD17: =_xlfn.TEXTJOIN("/",TRUE,IF(OfertaPlazas[[#This Row],[GITST]]="SI","GITST",""),IF(OfertaPlazas[[#This Row],[GIB]]="SI","GIB",""),IF(OfertaPlazas[[#This Row],[GISD]]="SI","GISD",""),IF(OfertaPlazas[[#This Row],[MASTER]]="SI","MASTER","")) -> GITST/MASTER | AE17: SI | AF17: SI | AG17: SI | AH17: SI | AI17: SI | AJ17: SI | AK17: SI | AL17: SI | AM17: SI | AN17: SI | AO17: SI | AP17: SI | AQ17: SI | AR17: NO | AS17: INGLÉS B2 o ALEMÁN B1 | AT17: INGLÉS B2 (TOEFL 90 IBT o IELTS 5.5 o CAE) y/o ALEMÁN B1 (TestDaF - Level 4 in all four examination areas- o Deutsche Sprachprüfung für den Hochschulzugang - Test of German Language Ability for International Students - (DSH, Level 2 or 3) o Deutsches Sprachdiplom der Kultusministerkonferenz - German Language Certificate of the Standing Conference of the German Ministers of Education and Cultural Affairs – Level 2 (KMK II) o The Kleines Deutsches Sprachdiplom - KDS- Großes Deutsches Sprachdiplom, or Zentrale Oberstufenprüfung - ZOP - (German language certificates of the Goethe Institute) o Deutsche Sprachprüfung II of the Sprachen- und Dolmetscher Institut München - German Language Examination II of the Language and Translators' Institute, Munich) | AU17: Bachelor en alemán. Master programm en inglés. El TFM se incluye en el LA cuando el alumno tenga un Supervisor en destino. Se puede agrupar meses | AY17: Institucional | AZ17: Electrical Engineering | BA17: Faculty of electrical Engineering and Information Technology | BC17: UPM (varias Escuelas) | BE17: =VLOOKUP(B17,'TEAMS_30-09-2021'!$D:$AG,30,FALSE) -> 0 | BF17: =VLOOKUP(B17,'ENCUESTAS JUN-2021'!I:I,1,FALSE) -> RWTH - Aachen | BG17: =VLOOKUP(B17,'TEAMS_30-09-2021'!D:D,1,FALSE) -> RWTH - Aachen | BL17: =VLOOKUP(E17,#REF!,1,FALSE) -> #REF!
A18: 17 | B18: Technische Universität Berlin (Faculty IV) | C18: Technische Universität Berlin | D18: Berlín | E18: D BERLIN02 | F18: DE | H18: 30 de abril (nomination) - 1 de junio (application) | I18: 04.30 | J18: 06.01 | K18: 31 de octubre (nomination) - 1 de diciembre (application) | L18: 10.31 | M18: 12.01 | N18: ER | P18: SÍ | Q18: SÍ | S18: Electrical Engineering (Electronics and Automation) / Computer Science (Information and CommunicationTechnologies) | T18: Sí | U18: 2 | V18: 12 | W18: exchange.programmes@tu-berlin.de | X18: Julia Fluthwedel, Laura Timmermann | Y18: SI | Z18: SI | AA18: NO | AB18: SI | AC18: SI | AD18: =_xlfn.TEXTJOIN("/",TRUE,IF(OfertaPlazas[[#This Row],[GITST]]="SI","GITST",""),IF(OfertaPlazas[[#This Row],[GIB]]="SI","GIB",""),IF(OfertaPlazas[[#This Row],[GISD]]="SI","GISD",""),IF(OfertaPlazas[[#This Row],[MASTER]]="SI","MASTER","")) -> GITST/GISD/MASTER | AE18: SI | AF18: SI | AG18: SI | AH18: SI | AI18: SI | AJ18: SI | AK18: SI | AL18: SI | AM18: SI | AN18: SI | AO18: SI | AP18: SI | AQ18: SI | AR18: NO | AS18: INGLÉS B2 (para TFM-TFG) o ALEMÁN A2 y B1 antes del comienzo del semestre (para asignaturas) | AT18: El Máster Elektrotechnik (Ingeniería Electrónica) se imparte en alemán y se precisa de un A2 en alemán para completar la Aplicación de destino.El Máster Computer Science (Informática) se imparte en inglés y no se precisa certificado de alemán. Ver información detallada en la web de la oficina internacional. .nivel ALEMÁN B1 requerido antes del comienzo del semestre para programas académicos en alemán. OJO: Anything above (B1, B2, C1, C2) can’t be older than 3 years at the time of the application deadline. Comprobad los requisitos de idiomas en la web de la TU Berlin según la titulación solicitada | AU18: Mínimo 160-180 ECTS superados para cursar asignaturas de Máster | AW18: No envían ToR en papel y su ToR no es verificable. Aceptamos el ToR si lo envía TU Berlín | AY18: Institucional | AZ18: Electrical Engineering | BA18: Institut für Teschniche Informatik and Mikroelectronik | BC18: UPM (varias Escuelas) | BD18: 20/1/2020 Narciso ha informado que en esta Universidad hay un profesor que ha estado con ellos en el GTI, para que los alumnos interesados sepan que pueden tener un contacto en la universidad de destino. | BE18: =VLOOKUP(B18,'TEAMS_30-09-2021'!$D:$AG,30,FALSE) -> #N/A | BF18: =VLOOKUP(B18,'ENCUESTAS JUN-2021'!I:I,1,FALSE) -> #N/A | BG18: =VLOOKUP(B18,'TEAMS_30-09-2021'!D:D,1,FALSE) -> #N/A
A19: 18 | B19: Rheinish Friedrich-Wilhems-Universität Bonn | C19: Rheinische Friedrich-Wilhelms-Universität Bonn | D19: Bonn | E19: D BONN01 | F19: DE | H19: 1 de mayo | I19: 05.01 | J19: 05.01 | K19: 1 de noviembre | L19: 11.01 | N19: ER | Q19: SÍ | S19: Computer Science (Information and CommunicationTechnologies) | T19: Sí | U19: 3 | V19: 12 | W19: erasmus-incoming@uni-bonn.de;programme-assist@uni-bonn.de; elmar.langetepe@informatik.uni-bonn.de | X19: Susanne Gittel-Avehounkpan; Elmar Langetepe . Manuela Meraner | Y19: SI | Z19: SI | AA19: NO | AB19: SI | AC19: SI | AD19: =_xlfn.TEXTJOIN("/",TRUE,IF(OfertaPlazas[[#This Row],[GITST]]="SI","GITST",""),IF(OfertaPlazas[[#This Row],[GIB]]="SI","GIB",""),IF(OfertaPlazas[[#This Row],[GISD]]="SI","GISD",""),IF(OfertaPlazas[[#This Row],[MASTER]]="SI","MASTER","")) -> GITST/GISD/MASTER | AE19: SI | AF19: SI | AG19: SI | AH19: SI | AI19: SI | AJ19: SI | AK19: SI | AL19: SI | AM19: SI | AN19: SI | AO19: SI | AP19: SI | AQ19: SI | AR19: NO | AS19: INGLÉS B2 o ALEMÁN B1 | AU19: Máster en inglés | AV19: Para el TFT hay que buscar y tener tutor en destino antes de iniciar la movilidad | AY19: Departamental | AZ19: Physics | BA19: Faculty of Natural Sciences: Physikalisches Institüt | BC19: ETSIT | BE19: =VLOOKUP(B19,'TEAMS_30-09-2021'!$D:$AG,30,FALSE) -> 0 | BF19: =VLOOKUP(B19,'ENCUESTAS JUN-2021'!I:I,1,FALSE) -> #N/A | BG19: =VLOOKUP(B19,'TEAMS_30-09-2021'!D:D,1,FALSE) -> Rheinish Friedrich-Wilhems-Universität Bonn
A20: 19 | B20: Technische Universität Braunschweig | C20: Technische Universität Braunschweig | E20: D BRAUNSC01 | F20: DE | H20: 30 de abril (nomination) - 31 de mayo (application) | I20: 04.30 | J20: 05.31 | K20: 31 de octubre (nomination) - 30 de noviembre (application) | L20: 10.31 | M20: 11.30 | N20: ER | P20: SÍ | S20: Electrical Engineering (Electronics and Automation) | T20: Sí | U20: 2 | V20: 12 | W20: exchange@tu-braunschweig.de | X20: Anne-Kathrin Kaiser | Y20: SI | Z20: SI | AA20: NO | AB20: NO | AC20: SI | AD20: =_xlfn.TEXTJOIN("/",TRUE,IF(OfertaPlazas[[#This Row],[GITST]]="SI","GITST",""),IF(OfertaPlazas[[#This Row],[GIB]]="SI","GIB",""),IF(OfertaPlazas[[#This Row],[GISD]]="SI","GISD",""),IF(OfertaPlazas[[#This Row],[MASTER]]="SI","MASTER","")) -> GITST/MASTER | AE20: SI | AF20: SI | AG20: SI | AH20: SI | AI20: SI | AJ20: SI | AK20: SI | AL20: SI | AM20: SI | AN20: SI | AO20: SI | AP20: SI | AQ20: SI | AR20: NO | AS20: ALEMÁN B1 o INGLÉS B1 | AU20: Mínimo 180 ECTS superados para cursar asignaturas de Máster | AV20: sube el número de alumnos de 1*12 a 2*12 15/01/2025 | AY20: Institucional | AZ20: Electronics Engineering | BC20: UPM (varias Escuelas) | BE20: =VLOOKUP(B20,'TEAMS_30-09-2021'!$D:$AG,30,FALSE) -> 0 | BF20: =VLOOKUP(B20,'ENCUESTAS JUN-2021'!I:I,1,FALSE) -> #N/A | BG20: =VLOOKUP(B20,'TEAMS_30-09-2021'!D:D,1,FALSE) -> Technische Universität Braunschweig
A21: 20 | B21: Technische Universität Darmstadt | C21: Technische Universität Darmstadt | D21: Darmstadt | E21: D DARMSTA01 | F21: DE | G21: 18 Meses | H21: 31 de marzo (nomination) - 30 de abril (application) | I21: 03.31 | J21: 04.30 | K21: 30 de septiembre (nomination) - 31 de octubre (application) | L21: 09.30 | M21: 10.31 | N21: ER | P21: SÍ | S21: Electrical Engineering (Electronics and Automation) | T21: Sí | U21: 4 | V21: 12 | W21: europe-incomings@pvw.tu-darmstadt.de | X21: Tanja Torres | Y21: SI | Z21: SI | AA21: NO | AB21: NO | AC21: SI | AD21: =_xlfn.TEXTJOIN("/",TRUE,IF(OfertaPlazas[[#This Row],[GITST]]="SI","GITST",""),IF(OfertaPlazas[[#This Row],[GIB]]="SI","GIB",""),IF(OfertaPlazas[[#This Row],[GISD]]="SI","GISD",""),IF(OfertaPlazas[[#This Row],[MASTER]]="SI","MASTER","")) -> GITST/MASTER | AE21: SI | AF21: SI | AG21: SI | AH21: SI | AI21: SI | AJ21: SI | AK21: SI | AL21: SI | AM21: SI | AN21: SI | AO21: SI | AP21: SI | AQ21: SI | AR21: SI | AS21: ALEMÁN A2 o INGLÉS B2 | AT21: + intensive German language course Para alumnos DT Inglés B2 Para alumnos DT Alemán: Goethe Certificate C1 | AU21: Para DT 90 ECTS (60ECTS de asignaturas y 30 de TFM). El Master de TU Darmstadt en inglés es: Master iCE (MICE = Master in Information and Communication Engineering). Duración 1año y medio + prorroga de max 1 año. El Máster en alemán: Master in Elektrotechnik und Informationstechnik / English courses: https://www.tucan.tu-darmstadt.de/scripts/mgrqcgi?APPNAME=CampusNet&PRGNAME=ACTION&ARGUMENTS=-ArRbQdVLqES91bsx53bxh1nfz5Sc3fPdqO2LhUfD4HVUxTtzHuqoJHc7CJmS6nO2o088NXhvM02sBmu5wKMaBzuB4gCU0ez5SiTxsNp50HT9SD9dB3t4Y7gLEDBa= | AY21: Institucional | AZ21: Electrical Engineering | BC21: UPM (varias Escuelas) | BE21: =VLOOKUP(B21,'TEAMS_30-09-2021'!$D:$AG,30,FALSE) -> 0 | BF21: =VLOOKUP(B21,'ENCUESTAS JUN-2021'!I:I,1,FALSE) -> #N/A | BG21: =VLOOKUP(B21,'TEAMS_30-09-2021'!D:D,1,FALSE) -> Technische Universität Darmstadt
A22: 21 | B22: Friedrich-Alexander Universität FAU | C22: Friedrich-Alexander-Universität Erlangen-Nürnberg | D22: Erlangen | E22: D ERLANGE01 | F22: DE | H22: 30 de abril (nomination) - 15 de mayo (application) | I22: 04.30 | J22: 05.15 | K22: 31 de octubre (application) - 15 de noviembre (nomination) | L22: 10.31 | M22: 11.15 | N22: ER | P22: SÍ | R22: SÍ | S22: Electrical Engineering (Electronics and Automation) / Biomedical Engineering (Medical Diagnosticand Treatment Technology) | T22: Sí | U22: 4 | V22: 10 | W22: mobility@fau.de | X22: international office | Y22: SI | Z22: SI | AA22: SI | AB22: NO | AC22: SI | AD22: =_xlfn.TEXTJOIN("/",TRUE,IF(OfertaPlazas[[#This Row],[GITST]]="SI","GITST",""),IF(OfertaPlazas[[#This Row],[GIB]]="SI","GIB",""),IF(OfertaPlazas[[#This Row],[GISD]]="SI","GISD",""),IF(OfertaPlazas[[#This Row],[MASTER]]="SI","MASTER","")) -> GITST/GIB/MASTER | AE22: SI | AF22: SI | AG22: SI | AH22: SI | AI22: SI | AJ22: SI | AK22: SI | AL22: SI | AM22: SI | AN22: SI | AO22: SI | AP22: SI | AQ22: SI | AR22: NO | AS22: ALEMÁN A2 o INGLÉS B2 o ALEMÁN B1 | AT22: Bachelor: ALEMÁN A2 o Inglés B2 // Master: Alemán B1 o Inglés B2 Official certificates (TOEFL, IELTS, DAF, etc.) or confirmations issued by a professional language teacher with stamp and signature are accepted. - for English: www.fau.de/files/2014/08/Programmstudierende_aus_dem_Ausland- Nachweis-Englischkenntnisse.pdf | AU22: Para hacer TFG en inglés es necesario buscar un tutor y consensuar con él el idioma. ENG para el Master "Communications and Multimedia Engineering (CME)" se requiere un nivel minimo de alemán A2 o es obligado hacer el curso intensivo de alemán en septiembre / 2*10 plazas en el area biomedical engineering y 2*10 plazas en el area Electronica engineering / Forma parte de EELISA | AY22: Departamental | AZ22: Electrical Engineering and Biomedical engineering | BA22: Hoch frenquenzentechnick and Zentralinstitüt für Medizintechnik | BC22: ETSIT | BE22: =VLOOKUP(B22,'TEAMS_30-09-2021'!$D:$AG,30,FALSE) -> ok | BF22: =VLOOKUP(B22,'ENCUESTAS JUN-2021'!I:I,1,FALSE) -> Friedrich-Alexander Universität FAU | BG22: =VLOOKUP(B22,'TEAMS_30-09-2021'!D:D,1,FALSE) -> Friedrich-Alexander Universität FAU
A23: 22 | B23: Hamburg University of Technology - TUHH | C23: Technische Universität Hamburg-Harburg | D23: Hamburg | E23: D HAMBURG03 | F23: DE | H23: 20 de abril (nomination) - 15 de junio (application) | I23: 04.20 | J23: 06.15 | K23: 20 de octubre (nomination) 15 de diciembre (application) | L23: 10.20 | M23: 12.15 | N23: ER | P23: SÍ | R23: SÍ | S23: Electrical Engineering (Electronics and Automation) / Biomedical Engineering (Medical Diagnosticand Treatment Technology) | T23: Sí | U23: 6 | V23: 12 | W23: internationaloffice@tuhh.de | X23: international office | Y23: SI | Z23: SI | AA23: SI | AB23: NO | AC23: SI | AD23: =_xlfn.TEXTJOIN("/",TRUE,IF(OfertaPlazas[[#This Row],[GITST]]="SI","GITST",""),IF(OfertaPlazas[[#This Row],[GIB]]="SI","GIB",""),IF(OfertaPlazas[[#This Row],[GISD]]="SI","GISD",""),IF(OfertaPlazas[[#This Row],[MASTER]]="SI","MASTER","")) -> GITST/GIB/MASTER | AE23: SI | AF23: SI | AG23: SI | AH23: SI | AI23: SI | AJ23: SI | AK23: SI | AL23: SI | AM23: SI | AN23: SI | AO23: SI | AP23: SI | AQ23: SI | AR23: NO | AS23: INGLÉS B2 o ALEMÁN B1 | AT23: (se acepta atestación firmada del departamento de lingüística) | AU23: asignaturas de Máster en inglés y Bachelor Engineering Science / 2 estudiantes en el área bio y 4 estudiantes en el área teleco | AY23: Departamental | AZ23: Electronics Automation and Biomedical Engineering | BA23: School of Electrical Engineering, Computer Sciences and Mathematic and School of Mechanical Engineering | BC23: ETSIT | BE23: =VLOOKUP(B23,'TEAMS_30-09-2021'!$D:$AG,30,FALSE) -> #N/A | BF23: =VLOOKUP(B23,'ENCUESTAS JUN-2021'!I:I,1,FALSE) -> #N/A | BG23: =VLOOKUP(B23,'TEAMS_30-09-2021'!D:D,1,FALSE) -> #N/A
A24: 23 | B24: Universität Kassel | C24: Universität Kassel | D24: Kassel | E24: D KASSEL01 | F24: DE | H24: 31 de mayo (nomination-application) | I24: 05.31 | J24: 05.31 | K24: 30 de noviembre (nomination-application) | L24: 11.30 | M24: 11.30 | N24: ER | O24: SÍ | P24: SÍ | Q24: SÍ | S24: Electrical Engineering: (Electricity and Energy); (Electronics and Automation) / ComputerScience (Information and CommunicationTechnologies) | T24: Sí | U24: 1 | V24: 12 | W24: exchange@uni-kassel.de | X24: international office | Y24: SI | Z24: SI | AA24: NO | AB24: SI | AC24: SI | AD24: =_xlfn.TEXTJOIN("/",TRUE,IF(OfertaPlazas[[#This Row],[GITST]]="SI","GITST",""),IF(OfertaPlazas[[#This Row],[GIB]]="SI","GIB",""),IF(OfertaPlazas[[#This Row],[GISD]]="SI","GISD",""),IF(OfertaPlazas[[#This Row],[MASTER]]="SI","MASTER","")) -> GITST/GISD/MASTER | AE24: SI | AF24: SI | AG24: SI | AH24: SI | AI24: SI | AJ24: SI | AK24: SI | AL24: SI | AM24: SI | AN24: SI | AO24: SI | AP24: SI | AQ24: SI | AR24: NO | AS24: INGLÉS B2 o ALEMÁN B1 | AU24: Algunas asignaturas en inglés, especialmete en el área 061 / posibilidad de TFM y TFG en inglés: la unviersidad aceptará las solicitudes "caso por caso" | AY24: Departamental | AZ24: Electronics Automation and Computer Science | BA24: Electrotechnik | BC24: ETSIT | BE24: =VLOOKUP(B24,'TEAMS_30-09-2021'!$D:$AG,30,FALSE) -> 0 | BF24: =VLOOKUP(B24,'ENCUESTAS JUN-2021'!I:I,1,FALSE) -> #N/A | BG24: =VLOOKUP(B24,'TEAMS_30-09-2021'!D:D,1,FALSE) -> Universität Kassel
A25: 24 | B25: Mannheim University of Applied Sciences | C25: Hochschule Mannheim | D25: Mannheim | E25: D MANNHEI03 | F25: DE | H25: 30 de abril(nomination)-31 de mayo(application) | I25: 04.30 | J25: 05.31 | K25: 30 septiembre (nomination) - 15 noviembre (application) | L25: 09.30 | M25: 11.15 | N25: ER | P25: SÍ | R25: SÍ | S25: Electrical Engineering (Electronics and Automation) / Biomedical Engineering (Medical Diagnosticand Treatment Technology) | T25: Sí | U25: 2 | V25: 12 | W25: erasmus.io@hs-mannheim.de;incoming.io@hs-mannheim.de | X25: Ms. Maria Mann | Y25: SI | Z25: SI | AA25: SI | AB25: NO | AC25: SI | AD25: =_xlfn.TEXTJOIN("/",TRUE,IF(OfertaPlazas[[#This Row],[GITST]]="SI","GITST",""),IF(OfertaPlazas[[#This Row],[GIB]]="SI","GIB",""),IF(OfertaPlazas[[#This Row],[GISD]]="SI","GISD",""),IF(OfertaPlazas[[#This Row],[MASTER]]="SI","MASTER","")) -> GITST/GIB/MASTER | AE25: SI | AF25: SI | AG25: SI | AH25: SI | AI25: SI | AJ25: NO | AK25: NO | AL25: NO | AM25: NO | AN25: SI | AO25: SI | AP25: NO | AQ25: SI | AR25: NO | AS25: ALEMÁN B1 o ALEMÁN A2 o INGLÉS B2 | AT25: + curso intensivo de alemán en septiembre | AU25: Biomédical engineering sólo en Departamento Tecnologías de la Información (NO con Departamento de Biotecnología) /Alemán para Bioingeniería médica / Inglés o Alemán para Electronics /Alemán para Bachelor y demás programas de Máster. Mínimo 180 ECTS superados para cursar asignaturas de Máster. | AV25: No se puede dividir el número de plazas | BE25: =VLOOKUP(B25,'TEAMS_30-09-2021'!$D:$AG,30,FALSE) -> #N/A | BF25: =VLOOKUP(B25,'ENCUESTAS JUN-2021'!I:I,1,FALSE) -> #N/A | BG25: =VLOOKUP(B25,'TEAMS_30-09-2021'!D:D,1,FALSE) -> #N/A
A26: 25 | B26: Technische Universität München | C26: Technische Universität München (TUM) | D26: München | E26: D MUNCHEN02 | F26: DE | H26: 30 de abril (nomination) - 10 de mayo (application) | I26: 04.30 | J26: 05.10 | K26: 17 de octubre (nomination) 31 de octubre (application) | L26: 10.17 | N26: ER | O26: SÍ | S26: Electrical Engineering (Electricity and Energy) | T26: Sí | U26: 3 | V26: 12 | W26: larissa.meier@tum.de | X26: Larissa Meier | Y26: SI | Z26: SI | AA26: NO | AB26: NO | AC26: SI | AD26: =_xlfn.TEXTJOIN("/",TRUE,IF(OfertaPlazas[[#This Row],[GITST]]="SI","GITST",""),IF(OfertaPlazas[[#This Row],[GIB]]="SI","GIB",""),IF(OfertaPlazas[[#This Row],[GISD]]="SI","GISD",""),IF(OfertaPlazas[[#This Row],[MASTER]]="SI","MASTER","")) -> GITST/MASTER | AE26: SI | AF26: SI | AG26: SI | AH26: SI | AI26: SI | AJ26: SI | AK26: SI | AL26: SI | AM26: SI | AN26: SI | AO26: SI | AP26: SI | AQ26: SI | AR26: NO | AS26: ALEMÁN B1 o INGLÉS B2 | AT26: (una atestación del departmento de lingüística es aceptada) | AU26: Se pueden cursar asignaturas de varios departamentos pero la mayoría deben ser de Electrical and Computer Engineering (at least 60%). Para movilidad de 1 semestre, solo hay un periodo de examinación. | AV26: Please only nominate students within the existing agreements between your university and TUM! Do not change the number of students or the TUM department, as we could not accept such nominations! - Al tratarse de un acuerdo en el marco de Electrical Engineering, al menos un 60% de los créditos a cursar deben corresponder a esta rama. No se puede dividir el número de plazas. RETOMAR ACUERDO INCLUIR 061 y 914 EN MAYO 2024 | AY26: Departamental | AZ26: Electrical Engineering | BA26: Faculty of Electrical Engineering and Information Technology | BC26: UPM (varias Escuelas) | BE26: =VLOOKUP(B26,'TEAMS_30-09-2021'!$D:$AG,30,FALSE) -> 0 | BF26: =VLOOKUP(B26,'ENCUESTAS JUN-2021'!I:I,1,FALSE) -> #N/A | BG26: =VLOOKUP(B26,'TEAMS_30-09-2021'!D:D,1,FALSE) -> Technische Universität München
A27: 26 | B27: Universität des Saarlandes | C27: Universität des Saarlandes | D27: Saarbruecken | E27: D SAARBRU01 | F27: DE | H27: 15 de junio (nomination)- 30 junio (application) | I27: 06.15 | J27: 06.30 | K27: 15 de diciembre (nomination) - 30 de diciembre (application) | L27: 12.15 | M27: 12.30 | N27: ER | P27: SÍ | Q27: SÍ | R27: Sí | S27: Electrical Engineering (Electronics and Automation) / Computer Science (Information and CommunicationTechnologies) / Biomedical Engineering | T27: Sí | U27: 2 | V27: 12 | W27: erasmus@io.uni-saarland.de; international@uni-saarland.de (IIA) | X27: Luis Lidon | Y27: SI | Z27: SI | AA27: SI | AB27: SI | AC27: SI | AD27: =_xlfn.TEXTJOIN("/",TRUE,IF(OfertaPlazas[[#This Row],[GITST]]="SI","GITST",""),IF(OfertaPlazas[[#This Row],[GIB]]="SI","GIB",""),IF(OfertaPlazas[[#This Row],[GISD]]="SI","GISD",""),IF(OfertaPlazas[[#This Row],[MASTER]]="SI","MASTER","")) -> GITST/GIB/GISD/MASTER | AE27: SI | AF27: SI | AG27: SI | AH27: SI | AI27: SI | AJ27: SI | AK27: SI | AL27: SI | AM27: SI | AN27: SI | AO27: SI | AP27: SI | AQ27: NO | AR27: NO | AS27: ALEMÁN B1 o INGLÉS B2 | AU27: asignaturas de Máster "Computer and Communication Technology" en inglés / 2 plazas para computer science / acuerdo con su UDS Systems Engineering. course catalogue: https://www.lsf.uni-saarland.de/qisserver/rds?state=wtree&search=1&trex=step&root120242=396627%7C397868%7C394098&P.vx=kurz uy acuerdo con UDS Computer Science | AY27: Departamental | AZ27: Electrical Engineering, Medical Technology and Computer Science | BA27: Mechatronik and Mathematics&Informatik | BC27: ETSIT | BE27: =VLOOKUP(B27,'TEAMS_30-09-2021'!$D:$AG,30,FALSE) -> 0 | BF27: =VLOOKUP(B27,'ENCUESTAS JUN-2021'!I:I,1,FALSE) -> Universität des Saarlandes | BG27: =VLOOKUP(B27,'TEAMS_30-09-2021'!D:D,1,FALSE) -> Universität des Saarlandes | BL27: =VLOOKUP(E27,#REF!,1,FALSE) -> #REF!
A28: 27 | B28: Universität Stuttgart | C28: Universität Stuttgart | D28: Stuttgart | E28: D STUTTGA01 | F28: DE | H28: 1 de abril (nomination) 1 de mayo (registration) 1 de junio (application) | I28: 04.01 | J28: 05.01 | K28: 1 de octubre (nomination) - 1 de noviembre (registration) - 1 de diciembre (application) | L28: 10.01 | M28: 11.01 | N28: ER | P28: SÍ | R28: SÍ | S28: Electrical Engineering (Electronics and Automation) / Biomedical Engineering (Medical Diagnosticand Treatment Technology) | T28: Sí | U28: 4 | V28: 12 | W28: incoming@ia.uni-stuttgart.de | X28: Rebecca Schwenger Silvia Cornacchiari | Y28: SI | Z28: SI | AA28: SI | AB28: NO | AC28: SI | AD28: =_xlfn.TEXTJOIN("/",TRUE,IF(OfertaPlazas[[#This Row],[GITST]]="SI","GITST",""),IF(OfertaPlazas[[#This Row],[GIB]]="SI","GIB",""),IF(OfertaPlazas[[#This Row],[GISD]]="SI","GISD",""),IF(OfertaPlazas[[#This Row],[MASTER]]="SI","MASTER","")) -> GITST/GIB/MASTER | AE28: SI | AF28: SI | AG28: SI | AH28: SI | AI28: SI | AJ28: SI | AK28: SI | AL28: SI | AM28: SI | AN28: SI | AO28: SI | AP28: SI | AQ28: SI | AR28: NO | AS28: INGLÉS B2 o ALEMÁN B2 | AT28: Junto con cursos intensivos de alemán | AU28: Para realizar e TFG o TFM el alumno deberá solicitar el curso entero y cursar asignaturas en el 1er semestre mientras el Proyecto se realizará en el 2ndo semestre / Mínimo 180 ECTS superados para cursar asignaturas de Máster /2 alumnos para 714 y 2 alumos para 914. | AY28: Institucional y Departamental | AZ28: Electrical Engineering and Information Technology, Biomedical Engineering | BC28: UPM (varias Escuelas) + ETSIT | BE28: =VLOOKUP(B28,'TEAMS_30-09-2021'!$D:$AG,30,FALSE) -> ok | BF28: =VLOOKUP(B28,'ENCUESTAS JUN-2021'!I:I,1,FALSE) -> Universität Stuttgart | BG28: =VLOOKUP(B28,'TEAMS_30-09-2021'!D:D,1,FALSE) -> Universität Stuttgart | BL28: =VLOOKUP(E28,#REF!,1,FALSE) -> #REF!
A29: 28 | B29: Aalborg University | C29: Aalborg Universitet | D29: Aalborg | E29: DK ALBORG01 | F29: DK | H29: 1 de abril (nomination) 15 de abril (application) | I29: 04.01 | J29: 04.15 | K29: 1 de octubre (nomination) - 15 de octubre (application) | L29: 10.10 | M29: 10.15 | N29: ER | P29: SÍ | S29: Electrical Engineering (Electronics and Automation) | T29: Sí | U29: 1 | V29: 12 | W29: internationaloffice@aau.dk; incoming-student@aau.dk; outgoing-student@adm.aau.dk | X29: Rikke Hougaard | Y29: SI | Z29: SI | AA29: NO | AB29: NO | AC29: SI | AD29: =_xlfn.TEXTJOIN("/",TRUE,IF(OfertaPlazas[[#This Row],[GITST]]="SI","GITST",""),IF(OfertaPlazas[[#This Row],[GIB]]="SI","GIB",""),IF(OfertaPlazas[[#This Row],[GISD]]="SI","GISD",""),IF(OfertaPlazas[[#This Row],[MASTER]]="SI","MASTER","")) -> GITST/MASTER | AE29: SI | AF29: SI | AG29: SI | AH29: SI | AI29: SI | AJ29: SI | AK29: SI | AL29: SI | AM29: SI | AN29: SI | AO29: SI | AP29: SI | AQ29: SI | AR29: NO | AS29: INGLÉS B2 | AT29: (IELTS 6.5 / TOEFL 85 with a minimum score of 20 in each section / Cambridge ESOL C1) | AU29: Campus en Aalborg y en Copenhagen. Mínimo 180 ECTS superados para cursar asignaturas de Máster. Se requiere cursar 30 ECTS/semestre. Para asignaturas de Electronics y IT, escoger asignaturas de "Innovative Communication Technologies and Entrepreneurship", "Signal Processing and Acoustics" y "Control and Automation" /Students can only choose course packages with the study board(s) that are covered by the exchange agreement with you as an exchange partner | AV29: En cuanto al TOEFL se podría hacer una excepción si una de las competencias tiene un 19 pero la suma general cumple con los requisitos | BE29: =VLOOKUP(B29,'TEAMS_30-09-2021'!$D:$AG,30,FALSE) -> 0 | BF29: =VLOOKUP(B29,'ENCUESTAS JUN-2021'!I:I,1,FALSE) -> #N/A | BG29: =VLOOKUP(B29,'TEAMS_30-09-2021'!D:D,1,FALSE) -> Aalborg University | BL29: =VLOOKUP(E29,#REF!,1,FALSE) -> #REF!
A30: 29 | B30: Technical University of Denmark - DTU | C30: Danmarks Tekniske Universitet | D30: Lyngby (Copenhague) | E30: DK LYNGBY01 | F30: DK | H30: 15 de abril | I30: 04.15 | J30: 04.15 | K30: 1 de noviembre | L30: 11.01 | N30: ER | P30: SÍ | Q30: SÍ | R30: SÍ | S30: Electrical Engineering (Electronics and Automation) / Biomedical Engineering / Computer Science | T30: Sí | U30: 2 | V30: 12 | W30: asmae@dtu.dk | X30: Astrid Marie Christiansen | Y30: SI | Z30: SI | AA30: SI | AB30: SI | AC30: SI | AD30: =_xlfn.TEXTJOIN("/",TRUE,IF(OfertaPlazas[[#This Row],[GITST]]="SI","GITST",""),IF(OfertaPlazas[[#This Row],[GIB]]="SI","GIB",""),IF(OfertaPlazas[[#This Row],[GISD]]="SI","GISD",""),IF(OfertaPlazas[[#This Row],[MASTER]]="SI","MASTER","")) -> GITST/GIB/GISD/MASTER | AE30: SI | AF30: SI | AG30: SI | AH30: SI | AI30: SI | AJ30: SI | AK30: SI | AL30: SI | AM30: SI | AN30: SI | AO30: SI | AP30: SI | AQ30: SI | AR30: NO | AS30: INGLÉS B2 | AT30: (atestación del departamento de lingüística válida) | AU30: Bachelor en Danés. Master en inglés. No se puede comenzar la Master's Thesis hasta Febrero y el periodo de realización es 5 meses. Min 20 ECTS por semestre http://www.dtu.dk/english/Education/Incoming-students/Exchange. | BE30: =VLOOKUP(B30,'TEAMS_30-09-2021'!$D:$AG,30,FALSE) -> #N/A | BF30: =VLOOKUP(B30,'ENCUESTAS JUN-2021'!I:I,1,FALSE) -> #N/A | BG30: =VLOOKUP(B30,'TEAMS_30-09-2021'!D:D,1,FALSE) -> #N/A
A31: 30 | B31: Université Marie et Louis Pasteur | C31: Université de Franche-Comté | D31: Besançon | E31: F BESANCO01 | F31: FR | H31: 15 de mayo (nomination)- 1 de junio (application) | I31: 05.15 | J31: 06.01 | K31: 15 de octubre (nomination) - 1 de noviembre (application) | L31: 10.15 | M31: 11.01 | N31: ER | R31: SÍ | S31: Biomedical Engineering (Medical Diagnosticand Treatment Technology) | T31: Sí | U31: 1 | V31: 12 | W31: michelle.parrenin@univ-fcomte.fr | X31: Michelle PARRENIN | Y31: SI | Z31: NO | AA31: SI | AB31: NO | AC31: SI | AD31: =_xlfn.TEXTJOIN("/",TRUE,IF(OfertaPlazas[[#This Row],[GITST]]="SI","GITST",""),IF(OfertaPlazas[[#This Row],[GIB]]="SI","GIB",""),IF(OfertaPlazas[[#This Row],[GISD]]="SI","GISD",""),IF(OfertaPlazas[[#This Row],[MASTER]]="SI","MASTER","")) -> GIB/MASTER | AE31: SI | AF31: SI | AG31: SI | AH31: SI | AI31: SI | AJ31: SI | AK31: SI | AL31: SI | AM31: SI | AN31: SI | AO31: SI | AP31: SI | AQ31: SI | AR31: NO | AS31: FRANCÉS B1 | AU31: Medical Technology | AV31: cambió el nombre universidad en marzo 2025 | AY31: Departamental | AZ31: 914 Biomedical Engineering | BA31: Medical diagnostic and treatmente technology | BB31: Jean-Marie CROLET - jean-marie.crolet@univ-fcmote.fr | BC31: UPM (varias Escuelas) | BE31: =VLOOKUP(B31,'TEAMS_30-09-2021'!$D:$AG,30,FALSE) -> #N/A | BF31: =VLOOKUP(B31,'ENCUESTAS JUN-2021'!I:I,1,FALSE) -> #N/A | BG31: =VLOOKUP(B31,'TEAMS_30-09-2021'!D:D,1,FALSE) -> #N/A
A32: 31 | B32: École pour l'Informatique et les Techniques Avancées - EPITA | C32: Ecole pour l'Informatique et les Techniques Avancées (EPITA) | D32: Paris | E32: F BICETRE02 | F32: FR | H32: 15 de mayo (nomination) - 30 de mayo (application) | I32: 05.15 | J32: 05.30 | K32: 15 de octubre (nomination) - 31 de octubre (application) | L32: 10.15 | M32: 10.31 | N32: ER | P32: SÍ | Q32: SÍ | S32: Electrical Engineering (Electronics and Automation) / Computer Science (Information and Communication Technologies) | T32: Sí | U32: 2 | V32: 12 | W32: international@epita.fr ; camille-chloe.moussa@epita.fr | X32: Camille-Chloé MOUSSA | Y32: SI | Z32: SI | AA32: NO | AB32: SI | AC32: SI | AD32: =_xlfn.TEXTJOIN("/",TRUE,IF(OfertaPlazas[[#This Row],[GITST]]="SI","GITST",""),IF(OfertaPlazas[[#This Row],[GIB]]="SI","GIB",""),IF(OfertaPlazas[[#This Row],[GISD]]="SI","GISD",""),IF(OfertaPlazas[[#This Row],[MASTER]]="SI","MASTER","")) -> GITST/GISD/MASTER | AE32: SI | AF32: SI | AG32: SI | AH32: SI | AI32: SI | AJ32: SI | AK32: SI | AL32: SI | AM32: SI | AN32: SI | AO32: SI | AP32: SI | AQ32: SI | AR32: NO | AS32: FRANCÉS B1 o INGLÉS B2 | AT32: INGLÉS B2(TOEFL (minimum score 550 ITP, 80 IBT) TOEIC (minimum score 750) IELTS (minimum score 6.0) Cambridge ESOL Examinations BULATS (B2) | AU32: Master degrees in English: https://www.epita.fr/en/degree-programs-english/ | AY32: Institucional | AZ32: 610 Computer Science | BB32: Eramus+ Coordinator: Ms Maria Hutler maria.hulter@epita.fr/Ms Nazima Canda mazima.canda@epifa.fr | BC32: UPM (varias Escuelas) | BD32: Acuerdo: 0610 Information and Communication Technologies | BE32: =VLOOKUP(B32,'TEAMS_30-09-2021'!$D:$AG,30,FALSE) -> #N/A | BF32: =VLOOKUP(B32,'ENCUESTAS JUN-2021'!I:I,1,FALSE) -> #N/A | BG32: =VLOOKUP(B32,'TEAMS_30-09-2021'!D:D,1,FALSE) -> #N/A
A33: 32 | B33: ENSEIRB MATMECA / IPB | C33: Bordeaux INP – Ecole Nationale Supérieure d’Electronique, Informatique, Télécommunications, Mathématiques et Mécanique (ENSEIRB-MATMECA) | D33: Bordeaux | E33: F BORDEAU54 | F33: FR | H33: 1 de mayo (nomination) 15 de mayo (application) | I33: 05.01 | J33: 05.15 | K33: 1 de noviemrbe (nomination) - 15 noviembre (application) | L33: 11.01 | M33: 11.15 | N33: ER | P33: SÍ | Q33: SÍ | S33: Electrical Engineering (Electronics and Automation) /Computer Science (Information and Communication Technologies) | T33: Sí | U33: 2 | V33: 12 | W33: iro@enseirb-matmeca.fr | X33: international office | Y33: SI | Z33: SI | AA33: NO | AB33: SI | AC33: SI | AD33: =_xlfn.TEXTJOIN("/",TRUE,IF(OfertaPlazas[[#This Row],[GITST]]="SI","GITST",""),IF(OfertaPlazas[[#This Row],[GIB]]="SI","GIB",""),IF(OfertaPlazas[[#This Row],[GISD]]="SI","GISD",""),IF(OfertaPlazas[[#This Row],[MASTER]]="SI","MASTER","")) -> GITST/GISD/MASTER | AE33: SI | AF33: SI | AG33: SI | AH33: SI | AI33: SI | AJ33: NO | AK33: SI | AL33: SI | AM33: SI | AN33: SI | AO33: SI | AP33: SI | AQ33: SI | AR33: NO | AS33: FRANCÉS B2 | AU33: • Programs taught in English are only available at Master level (Master 2): Automatic and Mecatronics in Automotive, Aeronautic and Space Industry Electronic systems for biomedical engineering Radio & Telecommunication Systems Advanced Modelling of Materials and Structures | AY33: Institucional | AZ33: ¿713 Electronics Engineering /y/o 714 Electrical Engineering ? | BB33: International Officer: Ms Marie-Odile Vasconcelos -iro@enseirb-matmeca.fr | BC33: ETSIT | BD33: Acuerdo: 071 Electronics and automation/Telecomunication- Aparece el área 725 Medical Tecnology sin plazas -Para teacher area 071 Electrical and Telecom Engin | BE33: =VLOOKUP(B33,'TEAMS_30-09-2021'!$D:$AG,30,FALSE) -> se añade el área 610 ICTs acordado con ENSEIRB | BF33: =VLOOKUP(B33,'ENCUESTAS JUN-2021'!I:I,1,FALSE) -> #N/A | BG33: =VLOOKUP(B33,'TEAMS_30-09-2021'!D:D,1,FALSE) -> ENSEIRB MATMECA / IPB
A34: 33 | B34: École Nationale d’Ingénieurs de Brest ENIB | C34: Ecole Nationale d'Ingénieurs de Brest | D34: Brest | E34: F BREST07 | F34: FR | H34: 15 de mayo | I34: 05.15 | J34: 05.15 | K34: 15 de noviembre | L34: 11.15 | M34: 11.15 | N34: ER | P34: SÍ | Q34: Sí | S34: Electrical Engineering (Electronics and Automation) / Computer Science (Information and Communication Technologies) | T34: Sí | U34: 3 | V34: 12 | W34: international@enib.fr; | X34: Katy LE BRIS | Y34: SI | Z34: SI | AA34: NO | AB34: SI | AC34: SI | AD34: =_xlfn.TEXTJOIN("/",TRUE,IF(OfertaPlazas[[#This Row],[GITST]]="SI","GITST",""),IF(OfertaPlazas[[#This Row],[GIB]]="SI","GIB",""),IF(OfertaPlazas[[#This Row],[GISD]]="SI","GISD",""),IF(OfertaPlazas[[#This Row],[MASTER]]="SI","MASTER","")) -> GITST/GISD/MASTER | AE34: SI | AF34: SI | AG34: SI | AH34: SI | AI34: SI | AJ34: SI | AK34: SI | AL34: SI | AM34: SI | AN34: SI | AO34: SI | AP34: SI | AQ34: SI | AR34: NO | AS34: FRANCÉS B2 o INGLÉS B2 | AT34: INGLÉS B2 (for project or bachelor/master thesis) | AU34: Every international student must attend a French language course throughout the year (a placement test will determine your group) | AY34: Institucional | AZ34: 714 Electrical Engineering | BB34: Institutional coordinator: Anne Pierre-Duplessix-anne.pierre-duplessix@telecom:bretagne.eu | BC34: ETSIT | BE34: =VLOOKUP(B34,'TEAMS_30-09-2021'!$D:$AG,30,FALSE) -> 0 | BF34: =VLOOKUP(B34,'ENCUESTAS JUN-2021'!I:I,1,FALSE) -> #N/A | BG34: =VLOOKUP(B34,'TEAMS_30-09-2021'!D:D,1,FALSE) -> École Nationale d’Ingénieurs de Brest ENIB
